Workbook

Sheet Executive Summary Dashboard
A1: SUPPLY CHAIN MIS | EXECUTIVE SUMMARY DASHBOARD
A2: Integrated Management Information System • Trailing 12-Month Supply Chain, Inventory, Procurement, Fulfillment & Supplier Analytics.
A4: Total Orders | C4: Total Sales | E4: Total Purchase Value | G4: Total Inventory Value | I4: Total Suppliers
A5: =COUNTA('Order Tracking'!$A$5:$A$604) -> 600 | C5: =SUM('Order Tracking'!$L$5:$L$604) -> 49134145 | E5: =SUM('Purchase Management'!$I$5:$I$224) -> 2.3810373e+08 | G5: =SUM('Inventory Management'!$O$5:$O$104) -> 98642688 | I5: =COUNTA('Supplier Database'!$A$5:$A$29) -> 25
A7: Total Products | C7: Pending Orders | E7: Delayed Orders | G7: Order Fulfillment Rate | I7: On-Time Delivery Rate
A8: =COUNTA('Product Master'!$A$5:$A$104) -> 100 | C8: =COUNTIF('Order Tracking'!$M$5:$M$604,"Pending") -> 78 | E8: =COUNTIF('Order Tracking'!$R$5:$R$604,">0") -> 233 | G8: =IFERROR(COUNTIF('Order Tracking'!$M$5:$M$604,"Delivered")/COUNTA('Order Tracking'!$A$5:$A$604),0) -> 0.58166667 | I8: =IFERROR(COUNTIFS('Order Tracking'!$M$5:$M$604,"Delivered",'Order Tracking'!$R$5:$R$604,0)/COUNTIF('Order Tracking'!$M$5:$M$604,"Delivered"),0) -> 0.59598854
A10: Interactive Dashboard Filters (Select dropdown values in yellow cells to filter live KPIs)
A11: Filter: Start Date | B11: Filter: End Date | C11: Filter: Region | D11: Filter: Product Category | E11: Filter: Order Status | F11: Filter: Supplier ID | G11: Filtered Orders | H11: Filtered Sales (₹) | I11: Filtered Delivered | J11: Filtered Fulfillment % | K11: Filtered Supplier PO Value (₹)
A12: 45931 | B12: 46326 | C12: All | D12: All | E12: All | F12: All | G12: =COUNTIFS('Order Tracking'!$B$5:$B$604,">="&A12,'Order Tracking'!$B$5:$B$604,"<="&B12,'Order Tracking'!$E$5:$E$604,IF(C12="All","*",C12),'Order Tracking'!$I$5:$I$604,IF(D12="All","*",D12),'Order Tracking'!$M$5:$M$604,IF(E12="All","*",E12)) -> 600 | H12: =SUMIFS('Order Tracking'!$L$5:$L$604,'Order Tracking'!$B$5:$B$604,">="&A12,'Order Tracking'!$B$5:$B$604,"<="&B12,'Order Tracking'!$E$5:$E$604,IF(C12="All","*",C12),'Order Tracking'!$I$5:$I$604,IF(D12="All","*",D12),'Order Tracking'!$M$5:$M$604,IF(E12="All","*",E12)) -> 49134145 | I12: =COUNTIFS('Order Tracking'!$B$5:$B$604,">="&A12,'Order Tracking'!$B$5:$B$604,"<="&B12,'Order Tracking'!$E$5:$E$604,IF(C12="All","*",C12),'Order Tracking'!$I$5:$I$604,IF(D12="All","*",D12),'Order Tracking'!$M$5:$M$604,"Delivered") -> 349 | J12: =IFERROR(I12/G12,0) -> 0.58166667 | K12: =SUMIFS('Purchase Management'!$I$5:$I$224,'Purchase Management'!$B$5:$B$224,">="&A12,'Purchase Management'!$B$5:$B$224,"<="&B12,'Purchase Management'!$C$5:$C$224,IF(F12="All","*",F12)) -> 2.3810373e+08
A15: Monthly Sales Trend | E15: Orders by Status | I15: Sales by Product Category
A16: Month | B16: Sales Revenue (₹) | C16: Orders | E16: Status | F16: Orders | G16: Share % | I16: Category | J16: Sales Revenue (₹) | K16: Units Ordered
A17: 45962 | B17: =SUMIFS('Order Tracking'!$L$5:$L$604,'Order Tracking'!$B$5:$B$604,">="&A17,'Order Tracking'!$B$5:$B$604,"<"&EDATE(A17,1)) -> 3891158.8 | C17: =COUNTIFS('Order Tracking'!$B$5:$B$604,">="&A17,'Order Tracking'!$B$5:$B$604,"<"&EDATE(A17,1)) -> 50 | E17: Delivered | F17: =COUNTIF('Order Tracking'!$M$5:$M$604,E17) -> 349 | G17: =IFERROR(F17/$A$5,0) -> 0.58166667 | I17: Electronics | J17: =SUMIFS('Order Tracking'!$L$5:$L$604,'Order Tracking'!$I$5:$I$604,I17) -> 7418459.1 | K17: =SUMIFS('Order Tracking'!$J$5:$J$604,'Order Tracking'!$I$5:$I$604,I17) -> 1026
A18: 45992 | B18: =SUMIFS('Order Tracking'!$L$5:$L$604,'Order Tracking'!$B$5:$B$604,">="&A18,'Order Tracking'!$B$5:$B$604,"<"&EDATE(A18,1)) -> 3173007.4 | C18: =COUNTIFS('Order Tracking'!$B$5:$B$604,">="&A18,'Order Tracking'!$B$5:$B$604,"<"&EDATE(A18,1)) -> 41 | E18: Pending | F18: =COUNTIF('Order Tracking'!$M$5:$M$604,E18) -> 78 | G18: =IFERROR(F18/$A$5,0) -> 0.13 | I18: Home & Kitchen | J18: =SUMIFS('Order Tracking'!$L$5:$L$604,'Order Tracking'!$I$5:$I$604,I18) -> 6359299.4 | K18: =SUMIFS('Order Tracking'!$J$5:$J$604,'Order Tracking'!$I$5:$I$604,I18) -> 995
A19: 46023 | B19: =SUMIFS('Order Tracking'!$L$5:$L$604,'Order Tracking'!$B$5:$B$604,">="&A19,'Order Tracking'!$B$5:$B$604,"<"&EDATE(A19,1)) -> 4091315.9 | C19: =COUNTIFS('Order Tracking'!$B$5:$B$604,">="&A19,'Order Tracking'!$B$5:$B$604,"<"&EDATE(A19,1)) -> 47 | E19: Processing | F19: =COUNTIF('Order Tracking'!$M$5:$M$604,E19) -> 76 | G19: =IFERROR(F19/$A$5,0) -> 0.12666667 | I19: Office Supplies | J19: =SUMIFS('Order Tracking'!$L$5:$L$604,'Order Tracking'!$I$5:$I$604,I19) -> 5066638.8 | K19: =SUMIFS('Order Tracking'!$J$5:$J$604,'Order Tracking'!$I$5:$I$604,I19) -> 1140
A20: 46054 | B20: =SUMIFS('Order Tracking'!$L$5:$L$604,'Order Tracking'!$B$5:$B$604,">="&A20,'Order Tracking'!$B$5:$B$604,"<"&EDATE(A20,1)) -> 2977863.2 | C20: =COUNTIFS('Order Tracking'!$B$5:$B$604,">="&A20,'Order Tracking'!$B$5:$B$604,"<"&EDATE(A20,1)) -> 38 | E20: Dispatched | F20: =COUNTIF('Order Tracking'!$M$5:$M$604,E20) -> 56 | G20: =IFERROR(F20/$A$5,0) -> 0.093333333 | I20: Personal Care | J20: =SUMIFS('Order Tracking'!$L$5:$L$604,'Order Tracking'!$I$5:$I$604,I20) -> 5583999.6 | K20: =SUMIFS('Order Tracking'!$J$5:$J$604,'Order Tracking'!$I$5:$I$604,I20) -> 886
A21: 46082 | B21: =SUMIFS('Order Tracking'!$L$5:$L$604,'Order Tracking'!$B$5:$B$604,">="&A21,'Order Tracking'!$B$5:$B$604,"<"&EDATE(A21,1)) -> 4855581 | C21: =COUNTIFS('Order Tracking'!$B$5:$B$604,">="&A21,'Order Tracking'!$B$5:$B$604,"<"&EDATE(A21,1)) -> 63 | E21: Cancelled | F21: =COUNTIF('Order Tracking'!$M$5:$M$604,E21) -> 41 | G21: =IFERROR(F21/$A$5,0) -> 0.068333333 | I21: Industrial | J21: =SUMIFS('Order Tracking'!$L$5:$L$604,'Order Tracking'!$I$5:$I$604,I21) -> 7605893.4 | K21: =SUMIFS('Order Tracking'!$J$5:$J$604,'Order Tracking'!$I$5:$I$604,I21) -> 1139
A22: 46113 | B22: =SUMIFS('Order Tracking'!$L$5:$L$604,'Order Tracking'!$B$5:$B$604,">="&A22,'Order Tracking'!$B$5:$B$604,"<"&EDATE(A22,1)) -> 3579994 | C22: =COUNTIFS('Order Tracking'!$B$5:$B$604,">="&A22,'Order Tracking'!$B$5:$B$604,"<"&EDATE(A22,1)) -> 43 | I22: Packaging | J22: =SUMIFS('Order Tracking'!$L$5:$L$604,'Order Tracking'!$I$5:$I$604,I22) -> 6074915.3 | K22: =SUMIFS('Order Tracking'!$J$5:$J$604,'Order Tracking'!$I$5:$I$604,I22) -> 992
A23: 46143 | B23: =SUMIFS('Order Tracking'!$L$5:$L$604,'Order Tracking'!$B$5:$B$604,">="&A23,'Order Tracking'!$B$5:$B$604,"<"&EDATE(A23,1)) -> 4170402.8 | C23: =COUNTIFS('Order Tracking'!$B$5:$B$604,">="&A23,'Order Tracking'!$B$5:$B$604,"<"&EDATE(A23,1)) -> 53 | I23: Apparel | J23: =SUMIFS('Order Tracking'!$L$5:$L$604,'Order Tracking'!$I$5:$I$604,I23) -> 6042303.9 | K23: =SUMIFS('Order Tracking'!$J$5:$J$604,'Order Tracking'!$I$5:$I$604,I23) -> 919
A24: 46174 | B24: =SUMIFS('Order Tracking'!$L$5:$L$604,'Order Tracking'!$B$5:$B$604,">="&A24,'Order Tracking'!$B$5:$B$604,"<"&EDATE(A24,1)) -> 3324809 | C24: =COUNTIFS('Order Tracking'!$B$5:$B$604,">="&A24,'Order Tracking'!$B$5:$B$604,"<"&EDATE(A24,1)) -> 39 | I24: Automotive | J24: =SUMIFS('Order Tracking'!$L$5:$L$604,'Order Tracking'!$I$5:$I$604,I24) -> 4982635.5 | K24: =SUMIFS('Order Tracking'!$J$5:$J$604,'Order Tracking'!$I$5:$I$604,I24) -> 937
A25: 46204 | B25: =SUMIFS('Order Tracking'!$L$5:$L$604,'Order Tracking'!$B$5:$B$604,">="&A25,'Order Tracking'!$B$5:$B$604,"<"&EDATE(A25,1)) -> 4635139.5 | C25: =COUNTIFS('Order Tracking'!$B$5:$B$604,">="&A25,'Order Tracking'!$B$5:$B$604,"<"&EDATE(A25,1)) -> 48
A26: 46235 | B26: =SUMIFS('Order Tracking'!$L$5:$L$604,'Order Tracking'!$B$5:$B$604,">="&A26,'Order Tracking'!$B$5:$B$604,"<"&EDATE(A26,1)) -> 4350130.2 | C26: =COUNTIFS('Order Tracking'!$B$5:$B$604,">="&A26,'Order Tracking'!$B$5:$B$604,"<"&EDATE(A26,1)) -> 56
A27: 46266 | B27: =SUMIFS('Order Tracking'!$L$5:$L$604,'Order Tracking'!$B$5:$B$604,">="&A27,'Order Tracking'!$B$5:$B$604,"<"&EDATE(A27,1)) -> 3937105 | C27: =COUNTIFS('Order Tracking'!$B$5:$B$604,">="&A27,'Order Tracking'!$B$5:$B$604,"<"&EDATE(A27,1)) -> 54
A28: 46296 | B28: =SUMIFS('Order Tracking'!$L$5:$L$604,'Order Tracking'!$B$5:$B$604,">="&A28,'Order Tracking'!$B$5:$B$604,"<"&EDATE(A28,1)) -> 1868048 | C28: =COUNTIFS('Order Tracking'!$B$5:$B$604,">="&A28,'Order Tracking'!$B$5:$B$604,"<"&EDATE(A28,1)) -> 17
A31: Inventory Value by Category | E31: Supplier Performance Comparison (Top 10) | I31: Monthly Order Fulfillment Trend
A32: Category | B32: Inventory Value (₹) | C32: Units in Stock | E32: Supplier Name | F32: Performance Score | G32: On-Time % | I32: Month | J32: Delivered Orders | K32: Fulfillment Rate
A33: Electronics | B33: =SUMIFS('Inventory Management'!$O$5:$O$104,'Inventory Management'!$C$5:$C$104,A33) -> 1860258.2 | C33: =SUMIFS('Inventory Management'!$K$5:$K$104,'Inventory Management'!$C$5:$C$104,A33) -> 794 | E33: ='Supplier Performance Dashboard'!B12 -> Apex Supplies | F33: ='Supplier Performance Dashboard'!K12 -> 85.9 | G33: ='Supplier Performance Dashboard'!J12 -> 0.75 | I33: 45962 | J33: =COUNTIFS('Order Tracking'!$B$5:$B$604,">="&I33,'Order Tracking'!$B$5:$B$604,"<"&EDATE(I33,1),'Order Tracking'!$M$5:$M$604,"Delivered") -> 23 | K33: =IFERROR(J33/COUNTIFS('Order Tracking'!$B$5:$B$604,">="&I33,'Order Tracking'!$B$5:$B$604,"<"&EDATE(I33,1)),0) -> 0.46
A34: Home & Kitchen | B34: =SUMIFS('Inventory Management'!$O$5:$O$104,'Inventory Management'!$C$5:$C$104,A34) -> 7122143 | C34: =SUMIFS('Inventory Management'!$K$5:$K$104,'Inventory Management'!$C$5:$C$104,A34) -> 1310 | E34: ='Supplier Performance Dashboard'!B13 -> Bright Distributors | F34: ='Supplier Performance Dashboard'!K13 -> 69.8 | G34: ='Supplier Performance Dashboard'!J13 -> 0.5 | I34: 45992 | J34: =COUNTIFS('Order Tracking'!$B$5:$B$604,">="&I34,'Order Tracking'!$B$5:$B$604,"<"&EDATE(I34,1),'Order Tracking'!$M$5:$M$604,"Delivered") -> 20 | K34: =IFERROR(J34/COUNTIFS('Order Tracking'!$B$5:$B$604,">="&I34,'Order Tracking'!$B$5:$B$604,"<"&EDATE(I34,1)),0) -> 0.48780488
A35: Office Supplies | B35: =SUMIFS('Inventory Management'!$O$5:$O$104,'Inventory Management'!$C$5:$C$104,A35) -> 13365786 | C35: =SUMIFS('Inventory Management'!$K$5:$K$104,'Inventory Management'!$C$5:$C$104,A35) -> 4891 | E35: ='Supplier Performance Dashboard'!B14 -> Core Industries | F35: ='Supplier Performance Dashboard'!K14 -> 45.5 | G35: ='Supplier Performance Dashboard'!J14 -> 0 | I35: 46023 | J35: =COUNTIFS('Order Tracking'!$B$5:$B$604,">="&I35,'Order Tracking'!$B$5:$B$604,"<"&EDATE(I35,1),'Order Tracking'!$M$5:$M$604,"Delivered") -> 33 | K35: =IFERROR(J35/COUNTIFS('Order Tracking'!$B$5:$B$604,">="&I35,'Order Tracking'!$B$5:$B$604,"<"&EDATE(I35,1)),0) -> 0.70212766
A36: Personal Care | B36: =SUMIFS('Inventory Management'!$O$5:$O$104,'Inventory Management'!$C$5:$C$104,A36) -> 13705603 | C36: =SUMIFS('Inventory Management'!$K$5:$K$104,'Inventory Management'!$C$5:$C$104,A36) -> 3350 | E36: ='Supplier Performance Dashboard'!B15 -> Delta Trading Co. | F36: ='Supplier Performance Dashboard'!K15 -> 70.2 | G36: ='Supplier Performance Dashboard'!J15 -> 0.5 | I36: 46054 | J36: =COUNTIFS('Order Tracking'!$B$5:$B$604,">="&I36,'Order Tracking'!$B$5:$B$604,"<"&EDATE(I36,1),'Order Tracking'!$M$5:$M$604,"Delivered") -> 26 | K36: =IFERROR(J36/COUNTIFS('Order Tracking'!$B$5:$B$604,">="&I36,'Order Tracking'!$B$5:$B$604,"<"&EDATE(I36,1)),0) -> 0.68421053
A37: Industrial | B37: =SUMIFS('Inventory Management'!$O$5:$O$104,'Inventory Management'!$C$5:$C$104,A37) -> 19204320 | C37: =SUMIFS('Inventory Management'!$K$5:$K$104,'Inventory Management'!$C$5:$C$104,A37) -> 3387 | E37: ='Supplier Performance Dashboard'!B16 -> Ever Logistics | F37: ='Supplier Performance Dashboard'!K16 -> 87.6 | G37: ='Supplier Performance Dashboard'!J16 -> 0.77777778 | I37: 46082 | J37: =COUNTIFS('Order Tracking'!$B$5:$B$604,">="&I37,'Order Tracking'!$B$5:$B$604,"<"&EDATE(I37,1),'Order Tracking'!$M$5:$M$604,"Delivered") -> 44 | K37: =IFERROR(J37/COUNTIFS('Order Tracking'!$B$5:$B$604,">="&I37,'Order Tracking'!$B$5:$B$604,"<"&EDATE(I37,1)),0) -> 0.6984127
A38: Packaging | B38: =SUMIFS('Inventory Management'!$O$5:$O$104,'Inventory Management'!$C$5:$C$104,A38) -> 15464877 | C38: =SUMIFS('Inventory Management'!$K$5:$K$104,'Inventory Management'!$C$5:$C$104,A38) -> 3682 | E38: ='Supplier Performance Dashboard'!B17 -> Frontier Wholesale | F38: ='Supplier Performance Dashboard'!K17 -> 64.1 | G38: ='Supplier Performance Dashboard'!J17 -> 0.28571429 | I38: 46113 | J38: =COUNTIFS('Order Tracking'!$B$5:$B$604,">="&I38,'Order Tracking'!$B$5:$B$604,"<"&EDATE(I38,1),'Order Tracking'!$M$5:$M$604,"Delivered") -> 24 | K38: =IFERROR(J38/COUNTIFS('Order Tracking'!$B$5:$B$604,">="&I38,'Order Tracking'!$B$5:$B$604,"<"&EDATE(I38,1)),0) -> 0.55813953
A39: Apparel | B39: =SUMIFS('Inventory Management'!$O$5:$O$104,'Inventory Management'!$C$5:$C$104,A39) -> 8559432.6 | C39: =SUMIFS('Inventory Management'!$K$5:$K$104,'Inventory Management'!$C$5:$C$104,A39) -> 2622 | E39: ='Supplier Performance Dashboard'!B18 -> Global Partners | F39: ='Supplier Performance Dashboard'!K18 -> 78.7 | G39: ='Supplier Performance Dashboard'!J18 -> 0.57142857 | I39: 46143 | J39: =COUNTIFS('Order Tracking'!$B$5:$B$604,">="&I39,'Order Tracking'!$B$5:$B$604,"<"&EDATE(I39,1),'Order Tracking'!$M$5:$M$604,"Delivered") -> 30 | K39: =IFERROR(J39/COUNTIFS('Order Tracking'!$B$5:$B$604,">="&I39,'Order Tracking'!$B$5:$B$604,"<"&EDATE(I39,1)),0) -> 0.56603774
A40: Automotive | B40: =SUMIFS('Inventory Management'!$O$5:$O$104,'Inventory Management'!$C$5:$C$104,A40) -> 19360269 | C40: =SUMIFS('Inventory Management'!$K$5:$K$104,'Inventory Management'!$C$5:$C$104,A40) -> 4389 | E40: ='Supplier Performance Dashboard'!B19 -> Horizon Supplies | F40: ='Supplier Performance Dashboard'!K19 -> 86.3 | G40: ='Supplier Performance Dashboard'!J19 -> 0.77777778 | I40: 46174 | J40: =COUNTIFS('Order Tracking'!$B$5:$B$604,">="&I40,'Order Tracking'!$B$5:$B$604,"<"&EDATE(I40,1),'Order Tracking'!$M$5:$M$604,"Delivered") -> 20 | K40: =IFERROR(J40/COUNTIFS('Order Tracking'!$B$5:$B$604,">="&I40,'Order Tracking'!$B$5:$B$604,"<"&EDATE(I40,1)),0) -> 0.51282051
E41: ='Supplier Performance Dashboard'!B20 -> Indus Distributors | F41: ='Supplier Performance Dashboard'!K20 -> 88.1 | G41: ='Supplier Performance Dashboard'!J20 -> 0.75 | I41: 46204 | J41: =COUNTIFS('Order Tracking'!$B$5:$B$604,">="&I41,'Order Tracking'!$B$5:$B$604,"<"&EDATE(I41,1),'Order Tracking'!$M$5:$M$604,"Delivered") -> 28 | K41: =IFERROR(J41/COUNTIFS('Order Tracking'!$B$5:$B$604,">="&I41,'Order Tracking'!$B$5:$B$604,"<"&EDATE(I41,1)),0) -> 0.58333333
E42: ='Supplier Performance Dashboard'!B21 -> Jupiter Industries | F42: ='Supplier Performance Dashboard'!K21 -> 87.6 | G42: ='Supplier Performance Dashboard'!J21 -> 0.77777778 | I42: 46235 | J42: =COUNTIFS('Order Tracking'!$B$5:$B$604,">="&I42,'Order Tracking'!$B$5:$B$604,"<"&EDATE(I42,1),'Order Tracking'!$M$5:$M$604,"Delivered") -> 35 | K42: =IFERROR(J42/COUNTIFS('Order Tracking'!$B$5:$B$604,">="&I42,'Order Tracking'!$B$5:$B$604,"<"&EDATE(I42,1)),0) -> 0.625
I43: 46266 | J43: =COUNTIFS('Order Tracking'!$B$5:$B$604,">="&I43,'Order Tracking'!$B$5:$B$604,"<"&EDATE(I43,1),'Order Tracking'!$M$5:$M$604,"Delivered") -> 26 | K43: =IFERROR(J43/COUNTIFS('Order Tracking'!$B$5:$B$604,">="&I43,'Order Tracking'!$B$5:$B$604,"<"&EDATE(I43,1)),0) -> 0.48148148
I44: 46296 | J44: =COUNTIFS('Order Tracking'!$B$5:$B$604,">="&I44,'Order Tracking'!$B$5:$B$604,"<"&EDATE(I44,1),'Order Tracking'!$M$5:$M$604,"Delivered") -> 8 | K44: =IFERROR(J44/COUNTIFS('Order Tracking'!$B$5:$B$604,">="&I44,'Order Tracking'!$B$5:$B$604,"<"&EDATE(I44,1)),0) -> 0.47058824
A47: Key Business Insights & Management Recommendations
A48: 1. Order Fulfillment & Delay Bottlenecks: 57.8% of total orders (347/600) are Delivered with a 59.4% On-Time Delivery Rate; Warehouse Backlog and Carrier Delay drive the largest share of delayed orders.
A49: 2. Inventory Replenishment Priorities: 20 SKUs are currently below Minimum Stock Level (11 Out-of-Stock, 9 Low-Stock); prioritize immediate POs using the Reorder Quantity column in Inventory Management.
...

Sheet Inventory Dashboard
A1: INVENTORY & STOCK AVAILABILITY DASHBOARD
A2: Monitors warehouse stock levels, inventory valuation (₹), stock movement trends, and low-stock replenishment priorities.
A4: Total SKUs | C4: Total Units in Stock | E4: Total Inventory Value | G4: Stock Availability Rate
A5: =COUNTA('Inventory Management'!$A$5:$A$104) -> 100 | C5: =SUM('Inventory Management'!$K$5:$K$104) -> 24425 | E5: =SUM('Inventory Management'!$O$5:$O$104) -> 98642688 | G5: =IFERROR(COUNTIF('Inventory Management'!$K$5:$K$104,">0")/COUNTA('Inventory Management'!$A$5:$A$104),0) -> 0.89
A7: Low-Stock Items | C7: Out-of-Stock Items | E7: Overstocked Items | G7: Healthy Stock Items
A8: =COUNTIF('Inventory Management'!$P$5:$P$104,"Low Stock") -> 9 | C8: =COUNTIF('Inventory Management'!$P$5:$P$104,"Out of Stock") -> 11 | E8: =COUNTIF('Inventory Management'!$P$5:$P$104,"Overstocked") -> 17 | G8: =COUNTIF('Inventory Management'!$P$5:$P$104,"Healthy Stock") -> 63
A10: Inventory by Category | E10: Inventory Value by Warehouse
A11: Category | B11: Units in Stock | C11: Inventory Value (₹) | E11: Warehouse | F11: Units in Stock | G11: Inventory Value (₹)
A12: Electronics | B12: =SUMIFS('Inventory Management'!$K$5:$K$104,'Inventory Management'!$C$5:$C$104,A12) -> 794 | C12: =SUMIFS('Inventory Management'!$O$5:$O$104,'Inventory Management'!$C$5:$C$104,A12) -> 1860258.2 | E12: Delhi WH | F12: =SUMIFS('Inventory Management'!$K$5:$K$104,'Inventory Management'!$F$5:$F$104,E12) -> 5601 | G12: =SUMIFS('Inventory Management'!$O$5:$O$104,'Inventory Management'!$F$5:$F$104,E12) -> 20277839
A13: Home & Kitchen | B13: =SUMIFS('Inventory Management'!$K$5:$K$104,'Inventory Management'!$C$5:$C$104,A13) -> 1310 | C13: =SUMIFS('Inventory Management'!$O$5:$O$104,'Inventory Management'!$C$5:$C$104,A13) -> 7122143 | E13: Bengaluru WH | F13: =SUMIFS('Inventory Management'!$K$5:$K$104,'Inventory Management'!$F$5:$F$104,E13) -> 4093 | G13: =SUMIFS('Inventory Management'!$O$5:$O$104,'Inventory Management'!$F$5:$F$104,E13) -> 18027088
A14: Office Supplies | B14: =SUMIFS('Inventory Management'!$K$5:$K$104,'Inventory Management'!$C$5:$C$104,A14) -> 4891 | C14: =SUMIFS('Inventory Management'!$O$5:$O$104,'Inventory Management'!$C$5:$C$104,A14) -> 13365786 | E14: Kolkata WH | F14: =SUMIFS('Inventory Management'!$K$5:$K$104,'Inventory Management'!$F$5:$F$104,E14) -> 3758 | G14: =SUMIFS('Inventory Management'!$O$5:$O$104,'Inventory Management'!$F$5:$F$104,E14) -> 21265259
A15: Personal Care | B15: =SUMIFS('Inventory Management'!$K$5:$K$104,'Inventory Management'!$C$5:$C$104,A15) -> 3350 | C15: =SUMIFS('Inventory Management'!$O$5:$O$104,'Inventory Management'!$C$5:$C$104,A15) -> 13705603 | E15: Mumbai WH | F15: =SUMIFS('Inventory Management'!$K$5:$K$104,'Inventory Management'!$F$5:$F$104,E15) -> 6712 | G15: =SUMIFS('Inventory Management'!$O$5:$O$104,'Inventory Management'!$F$5:$F$104,E15) -> 25971115
A16: Industrial | B16: =SUMIFS('Inventory Management'!$K$5:$K$104,'Inventory Management'!$C$5:$C$104,A16) -> 3387 | C16: =SUMIFS('Inventory Management'!$O$5:$O$104,'Inventory Management'!$C$5:$C$104,A16) -> 19204320 | E16: Raipur WH | F16: =SUMIFS('Inventory Management'!$K$5:$K$104,'Inventory Management'!$F$5:$F$104,E16) -> 4261 | G16: =SUMIFS('Inventory Management'!$O$5:$O$104,'Inventory Management'!$F$5:$F$104,E16) -> 13101387
A17: Packaging | B17: =SUMIFS('Inventory Management'!$K$5:$K$104,'Inventory Management'!$C$5:$C$104,A17) -> 3682 | C17: =SUMIFS('Inventory Management'!$O$5:$O$104,'Inventory Management'!$C$5:$C$104,A17) -> 15464877
A18: Apparel | B18: =SUMIFS('Inventory Management'!$K$5:$K$104,'Inventory Management'!$C$5:$C$104,A18) -> 2622 | C18: =SUMIFS('Inventory Management'!$O$5:$O$104,'Inventory Management'!$C$5:$C$104,A18) -> 8559432.6
A19: Automotive | B19: =SUMIFS('Inventory Management'!$K$5:$K$104,'Inventory Management'!$C$5:$C$104,A19) -> 4389 | C19: =SUMIFS('Inventory Management'!$O$5:$O$104,'Inventory Management'!$C$5:$C$104,A19) -> 19360269
A22: Stock Movement Trends (Monthly Units Received vs. Units Sold)
A23: Month | B23: Stock Received (POs) | C23: Units Sold (Orders) | D23: Net Stock Change
A24: 45962 | B24: =SUMIFS('Purchase Management'!$L$5:$L$224,'Purchase Management'!$B$5:$B$224,">="&A24,'Purchase Management'!$B$5:$B$224,"<"&EDATE(A24,1)) -> 2472 | C24: =SUMIFS('Order Tracking'!$J$5:$J$604,'Order Tracking'!$B$5:$B$604,">="&A24,'Order Tracking'!$B$5:$B$604,"<"&EDATE(A24,1),'Order Tracking'!$M$5:$M$604,"<>Cancelled") -> 680 | D24: =B24-C24 -> 1792
A25: 45992 | B25: =SUMIFS('Purchase Management'!$L$5:$L$224,'Purchase Management'!$B$5:$B$224,">="&A25,'Purchase Management'!$B$5:$B$224,"<"&EDATE(A25,1)) -> 2670 | C25: =SUMIFS('Order Tracking'!$J$5:$J$604,'Order Tracking'!$B$5:$B$604,">="&A25,'Order Tracking'!$B$5:$B$604,"<"&EDATE(A25,1),'Order Tracking'!$M$5:$M$604,"<>Cancelled") -> 499 | D25: =B25-C25 -> 2171
A26: 46023 | B26: =SUMIFS('Purchase Management'!$L$5:$L$224,'Purchase Management'!$B$5:$B$224,">="&A26,'Purchase Management'!$B$5:$B$224,"<"&EDATE(A26,1)) -> 2377 | C26: =SUMIFS('Order Tracking'!$J$5:$J$604,'Order Tracking'!$B$5:$B$604,">="&A26,'Order Tracking'!$B$5:$B$604,"<"&EDATE(A26,1),'Order Tracking'!$M$5:$M$604,"<>Cancelled") -> 581 | D26: =B26-C26 -> 1796
A27: 46054 | B27: =SUMIFS('Purchase Management'!$L$5:$L$224,'Purchase Management'!$B$5:$B$224,">="&A27,'Purchase Management'!$B$5:$B$224,"<"&EDATE(A27,1)) -> 1316 | C27: =SUMIFS('Order Tracking'!$J$5:$J$604,'Order Tracking'!$B$5:$B$604,">="&A27,'Order Tracking'!$B$5:$B$604,"<"&EDATE(A27,1),'Order Tracking'!$M$5:$M$604,"<>Cancelled") -> 511 | D27: =B27-C27 -> 805
A28: 46082 | B28: =SUMIFS('Purchase Management'!$L$5:$L$224,'Purchase Management'!$B$5:$B$224,">="&A28,'Purchase Management'!$B$5:$B$224,"<"&EDATE(A28,1)) -> 3722 | C28: =SUMIFS('Order Tracking'!$J$5:$J$604,'Order Tracking'!$B$5:$B$604,">="&A28,'Order Tracking'!$B$5:$B$604,"<"&EDATE(A28,1),'Order Tracking'!$M$5:$M$604,"<>Cancelled") -> 781 | D28: =B28-C28 -> 2941
A29: 46113 | B29: =SUMIFS('Purchase Management'!$L$5:$L$224,'Purchase Management'!$B$5:$B$224,">="&A29,'Purchase Management'!$B$5:$B$224,"<"&EDATE(A29,1)) -> 2100 | C29: =SUMIFS('Order Tracking'!$J$5:$J$604,'Order Tracking'!$B$5:$B$604,">="&A29,'Order Tracking'!$B$5:$B$604,"<"&EDATE(A29,1),'Order Tracking'!$M$5:$M$604,"<>Cancelled") -> 516 | D29: =B29-C29 -> 1584
A30: 46143 | B30: =SUMIFS('Purchase Management'!$L$5:$L$224,'Purchase Management'!$B$5:$B$224,">="&A30,'Purchase Management'!$B$5:$B$224,"<"&EDATE(A30,1)) -> 5569 | C30: =SUMIFS('Order Tracking'!$J$5:$J$604,'Order Tracking'!$B$5:$B$604,">="&A30,'Order Tracking'!$B$5:$B$604,"<"&EDATE(A30,1),'Order Tracking'!$M$5:$M$604,"<>Cancelled") -> 691 | D30: =B30-C30 -> 4878
A31: 46174 | B31: =SUMIFS('Purchase Management'!$L$5:$L$224,'Purchase Management'!$B$5:$B$224,">="&A31,'Purchase Management'!$B$5:$B$224,"<"&EDATE(A31,1)) -> 2339 | C31: =SUMIFS('Order Tracking'!$J$5:$J$604,'Order Tracking'!$B$5:$B$604,">="&A31,'Order Tracking'!$B$5:$B$604,"<"&EDATE(A31,1),'Order Tracking'!$M$5:$M$604,"<>Cancelled") -> 472 | D31: =B31-C31 -> 1867
A32: 46204 | B32: =SUMIFS('Purchase Management'!$L$5:$L$224,'Purchase Management'!$B$5:$B$224,">="&A32,'Purchase Management'!$B$5:$B$224,"<"&EDATE(A32,1)) -> 3525 | C32: =SUMIFS('Order Tracking'!$J$5:$J$604,'Order Tracking'!$B$5:$B$604,">="&A32,'Order Tracking'!$B$5:$B$604,"<"&EDATE(A32,1),'Order Tracking'!$M$5:$M$604,"<>Cancelled") -> 634 | D32: =B32-C32 -> 2891
A33: 46235 | B33: =SUMIFS('Purchase Management'!$L$5:$L$224,'Purchase Management'!$B$5:$B$224,">="&A33,'Purchase Management'!$B$5:$B$224,"<"&EDATE(A33,1)) -> 3017 | C33: =SUMIFS('Order Tracking'!$J$5:$J$604,'Order Tracking'!$B$5:$B$604,">="&A33,'Order Tracking'!$B$5:$B$604,"<"&EDATE(A33,1),'Order Tracking'!$M$5:$M$604,"<>Cancelled") -> 666 | D33: =B33-C33 -> 2351
A34: 46266 | B34: =SUMIFS('Purchase Management'!$L$5:$L$224,'Purchase Management'!$B$5:$B$224,">="&A34,'Purchase Management'!$B$5:$B$224,"<"&EDATE(A34,1)) -> 3388 | C34: =SUMIFS('Order Tracking'!$J$5:$J$604,'Order Tracking'!$B$5:$B$604,">="&A34,'Order Tracking'!$B$5:$B$604,"<"&EDATE(A34,1),'Order Tracking'!$M$5:$M$604,"<>Cancelled") -> 564 | D34: =B34-C34 -> 2824
A35: 46296 | B35: =SUMIFS('Purchase Management'!$L$5:$L$224,'Purchase Management'!$B$5:$B$224,">="&A35,'Purchase Management'!$B$5:$B$224,"<"&EDATE(A35,1)) -> 2751 | C35: =SUMIFS('Order Tracking'!$J$5:$J$604,'Order Tracking'!$B$5:$B$604,">="&A35,'Order Tracking'!$B$5:$B$604,"<"&EDATE(A35,1),'Order Tracking'!$M$5:$M$604,"<>Cancelled") -> 235 | D35: =B35-C35 -> 2516
A38: Low-Stock & Out-of-Stock Product Replenishment Analysis
A39: Product ID | B39: Product Name | C39: Category | D39: Warehouse | E39: Closing Stock | F39: Minimum Stock | G39: Stock Status | H39: Reorder Qty
A40: ='Inventory Management'!A5 -> PRD001 | B40: ='Inventory Management'!B5 -> Everyday Electronics Item 001 | C40: ='Inventory Management'!C5 -> Electronics | D40: ='Inventory Management'!F5 -> Mumbai WH | E40: ='Inventory Management'!K5 -> 0 | F40: ='Inventory Management'!L5 -> 55 | G40: ='Inventory Management'!P5 -> Out of Stock | H40: ='Inventory Management'!Q5 -> 275
A41: ='Inventory Management'!A6 -> PRD002 | B41: ='Inventory Management'!B6 -> Premium Home Item 002 | C41: ='Inventory Management'!C6 -> Home & Kitchen | D41: ='Inventory Management'!F6 -> Raipur WH | E41: ='Inventory Management'!K6 -> 9 | F41: ='Inventory Management'!L6 -> 42 | G41: ='Inventory Management'!P6 -> Low Stock | H41: ='Inventory Management'!Q6 -> 285
A42: ='Inventory Management'!A9 -> PRD005 | B42: ='Inventory Management'!B9 -> Everyday Industrial Item 005 | C42: ='Inventory Management'!C9 -> Industrial | D42: ='Inventory Management'!F9 -> Delhi WH | E42: ='Inventory Management'!K9 -> 0 | F42: ='Inventory Management'!L9 -> 28 | G42: ='Inventory Management'!P9 -> Out of Stock | H42: ='Inventory Management'!Q9 -> 112
A43: ='Inventory Management'!A13 -> PRD009 | B43: ='Inventory Management'!B13 -> Essential Electronics Item 009 | C43: ='Inventory Management'!C13 -> Electronics | D43: ='Inventory Management'!F13 -> Delhi WH | E43: ='Inventory Management'!K13 -> 0 | F43: ='Inventory Management'!L13 -> 24 | G43: ='Inventory Management'!P13 -> Out of Stock | H43: ='Inventory Management'!Q13 -> 96
A44: ='Inventory Management'!A14 -> PRD010 | B44: ='Inventory Management'!B14 -> Essential Home Item 010 | C44: ='Inventory Management'!C14 -> Home & Kitchen | D44: ='Inventory Management'!F14 -> Delhi WH | E44: ='Inventory Management'!K14 -> 22 | F44: ='Inventory Management'!L14 -> 33 | G44: ='Inventory Management'!P14 -> Low Stock | H44: ='Inventory Management'!Q14 -> 275
A45: ='Inventory Management'!A21 -> PRD017 | B45: ='Inventory Management'!B21 -> Premium Electronics Item 017 | C45: ='Inventory Management'!C21 -> Electronics | D45: ='Inventory Management'!F21 -> Kolkata WH | E45: ='Inventory Management'!K21 -> 0 | F45: ='Inventory Management'!L21 -> 59 | G45: ='Inventory Management'!P21 -> Out of Stock | H45: ='Inventory Management'!Q21 -> 472
A46: ='Inventory Management'!A29 -> PRD025 | B46: ='Inventory Management'!B29 -> Pro Electronics Item 025 | C46: ='Inventory Management'!C29 -> Electronics | D46: ='Inventory Management'!F29 -> Kolkata WH | E46: ='Inventory Management'!K29 -> 0 | F46: ='Inventory Management'!L29 -> 56 | G46: ='Inventory Management'!P29 -> Out of Stock | H46: ='Inventory Management'!Q29 -> 224
A47: ='Inventory Management'!A30 -> PRD026 | B47: ='Inventory Management'!B30 -> Classic Home Item 026 | C47: ='Inventory Management'!C30 -> Home & Kitchen | D47: ='Inventory Management'!F30 -> Kolkata WH | E47: ='Inventory Management'!K30 -> 20 | F47: ='Inventory Management'!L30 -> 25 | G47: ='Inventory Management'!P30 -> Low Stock | H47: ='Inventory Management'!Q30 -> 80
...

Sheet Order Management Dashboard
A1: ORDER MANAGEMENT & FULFILLMENT DASHBOARD
A2: Tracks order processing, regional fulfillment, delivery turnaround time (TAT), delay root causes, and urgent order exceptions.
A4: Total Orders | C4: Completed Orders | E4: Pending Orders | G4: Processing Orders | I4: Cancelled Orders
A5: =COUNTA('Order Tracking'!$A$5:$A$604) -> 600 | C5: =COUNTIF('Order Tracking'!$M$5:$M$604,"Delivered") -> 349 | E5: =COUNTIF('Order Tracking'!$M$5:$M$604,"Pending") -> 78 | G5: =COUNTIF('Order Tracking'!$M$5:$M$604,"Processing") -> 76 | I5: =COUNTIF('Order Tracking'!$M$5:$M$604,"Cancelled") -> 41
A7: Delayed Orders | C7: Average Order Value | E7: Average Delivery TAT | G7: Order Fulfillment Rate | I7: On-Time Delivery Rate
A8: =COUNTIF('Order Tracking'!$R$5:$R$604,">0") -> 233 | C8: =IFERROR(AVERAGE('Order Tracking'!$L$5:$L$604),0) -> 81890.242 | E8: =IFERROR(AVERAGEIFS('Order Tracking'!$Q$5:$Q$604,'Order Tracking'!$M$5:$M$604,"Delivered"),0) -> 6.756447 | G8: =IFERROR(COUNTIF('Order Tracking'!$M$5:$M$604,"Delivered")/COUNTA('Order Tracking'!$A$5:$A$604),0) -> 0.58166667 | I8: =IFERROR(COUNTIFS('Order Tracking'!$M$5:$M$604,"Delivered",'Order Tracking'!$R$5:$R$604,0)/COUNTIF('Order Tracking'!$M$5:$M$604,"Delivered"),0) -> 0.59598854
A10: Orders by Status | E10: Orders by Region | I10: Delayed Orders by Reason
A11: Order Status | B11: Orders | C11: Share % | E11: Region | F11: Orders | G11: Sales Value (₹) | I11: Delay Reason | J11: Orders | K11: Share %
A12: Delivered | B12: =COUNTIF('Order Tracking'!$M$5:$M$604,A12) -> 349 | C12: =IFERROR(B12/$A$5,0) -> 0.58166667 | E12: North | F12: =COUNTIF('Order Tracking'!$E$5:$E$604,E12) -> 113 | G12: =SUMIFS('Order Tracking'!$L$5:$L$604,'Order Tracking'!$E$5:$E$604,E12) -> 9382569.8 | I12: Warehouse backlog | J12: =COUNTIFS('Order Tracking'!$T$5:$T$604,I12,'Order Tracking'!$R$5:$R$604,">0") -> 64 | K12: =IFERROR(J12/$A$8,0) -> 0.27467811
A13: Pending | B13: =COUNTIF('Order Tracking'!$M$5:$M$604,A13) -> 78 | C13: =IFERROR(B13/$A$5,0) -> 0.13 | E13: South | F13: =COUNTIF('Order Tracking'!$E$5:$E$604,E13) -> 109 | G13: =SUMIFS('Order Tracking'!$L$5:$L$604,'Order Tracking'!$E$5:$E$604,E13) -> 7999582.5 | I13: Awaiting stock | J13: =COUNTIFS('Order Tracking'!$T$5:$T$604,I13,'Order Tracking'!$R$5:$R$604,">0") -> 28 | K13: =IFERROR(J13/$A$8,0) -> 0.12017167
A14: Processing | B14: =COUNTIF('Order Tracking'!$M$5:$M$604,A14) -> 76 | C14: =IFERROR(B14/$A$5,0) -> 0.12666667 | E14: East | F14: =COUNTIF('Order Tracking'!$E$5:$E$604,E14) -> 119 | G14: =SUMIFS('Order Tracking'!$L$5:$L$604,'Order Tracking'!$E$5:$E$604,E14) -> 10093289 | I14: Address issue | J14: =COUNTIFS('Order Tracking'!$T$5:$T$604,I14,'Order Tracking'!$R$5:$R$604,">0") -> 30 | K14: =IFERROR(J14/$A$8,0) -> 0.12875536
A15: Dispatched | B15: =COUNTIF('Order Tracking'!$M$5:$M$604,A15) -> 56 | C15: =IFERROR(B15/$A$5,0) -> 0.093333333 | E15: West | F15: =COUNTIF('Order Tracking'!$E$5:$E$604,E15) -> 140 | G15: =SUMIFS('Order Tracking'!$L$5:$L$604,'Order Tracking'!$E$5:$E$604,E15) -> 12258217 | I15: Supplier delay | J15: =COUNTIFS('Order Tracking'!$T$5:$T$604,I15,'Order Tracking'!$R$5:$R$604,">0") -> 26 | K15: =IFERROR(J15/$A$8,0) -> 0.11158798
A16: Cancelled | B16: =COUNTIF('Order Tracking'!$M$5:$M$604,A16) -> 41 | C16: =IFERROR(B16/$A$5,0) -> 0.068333333 | E16: Central | F16: =COUNTIF('Order Tracking'!$E$5:$E$604,E16) -> 119 | G16: =SUMIFS('Order Tracking'!$L$5:$L$604,'Order Tracking'!$E$5:$E$604,E16) -> 9400486.9 | I16: Weather disruption | J16: =COUNTIFS('Order Tracking'!$T$5:$T$604,I16,'Order Tracking'!$R$5:$R$604,">0") -> 29 | K16: =IFERROR(J16/$A$8,0) -> 0.12446352
I17: Carrier delay | J17: =COUNTIFS('Order Tracking'!$T$5:$T$604,I17,'Order Tracking'!$R$5:$R$604,">0") -> 45 | K17: =IFERROR(J17/$A$8,0) -> 0.19313305
I18: Payment hold | J18: =COUNTIFS('Order Tracking'!$T$5:$T$604,I18,'Order Tracking'!$R$5:$R$604,">0") -> 11 | K18: =IFERROR(J18/$A$8,0) -> 0.0472103
A21: Monthly Order Volume | E21: Delivery Performance Breakdown
A22: Month | B22: Order Volume | C22: Delivered Orders | E22: Delivery Outcome | F22: Orders | G22: Share %
A23: 45962 | B23: =COUNTIFS('Order Tracking'!$B$5:$B$604,">="&A23,'Order Tracking'!$B$5:$B$604,"<"&EDATE(A23,1)) -> 50 | C23: =COUNTIFS('Order Tracking'!$B$5:$B$604,">="&A23,'Order Tracking'!$B$5:$B$604,"<"&EDATE(A23,1),'Order Tracking'!$M$5:$M$604,"Delivered") -> 23 | E23: On-Time Delivered | F23: =COUNTIFS('Order Tracking'!$M$5:$M$604,"Delivered",'Order Tracking'!$R$5:$R$604,0) -> 208 | G23: =IFERROR(F23/$A$5,0) -> 0.34666667
A24: 45992 | B24: =COUNTIFS('Order Tracking'!$B$5:$B$604,">="&A24,'Order Tracking'!$B$5:$B$604,"<"&EDATE(A24,1)) -> 41 | C24: =COUNTIFS('Order Tracking'!$B$5:$B$604,">="&A24,'Order Tracking'!$B$5:$B$604,"<"&EDATE(A24,1),'Order Tracking'!$M$5:$M$604,"Delivered") -> 20 | E24: Late Delivered | F24: =COUNTIFS('Order Tracking'!$M$5:$M$604,"Delivered",'Order Tracking'!$R$5:$R$604,">0") -> 141 | G24: =IFERROR(F24/$A$5,0) -> 0.235
A25: 46023 | B25: =COUNTIFS('Order Tracking'!$B$5:$B$604,">="&A25,'Order Tracking'!$B$5:$B$604,"<"&EDATE(A25,1)) -> 47 | C25: =COUNTIFS('Order Tracking'!$B$5:$B$604,">="&A25,'Order Tracking'!$B$5:$B$604,"<"&EDATE(A25,1),'Order Tracking'!$M$5:$M$604,"Delivered") -> 33 | E25: In-Transit (Dispatched) | F25: =COUNTIF('Order Tracking'!$M$5:$M$604,"Dispatched") -> 56 | G25: =IFERROR(F25/$A$5,0) -> 0.093333333
A26: 46054 | B26: =COUNTIFS('Order Tracking'!$B$5:$B$604,">="&A26,'Order Tracking'!$B$5:$B$604,"<"&EDATE(A26,1)) -> 38 | C26: =COUNTIFS('Order Tracking'!$B$5:$B$604,">="&A26,'Order Tracking'!$B$5:$B$604,"<"&EDATE(A26,1),'Order Tracking'!$M$5:$M$604,"Delivered") -> 26 | E26: Open Queue (Pending/Processing) | F26: =COUNTIF('Order Tracking'!$M$5:$M$604,"Pending")+COUNTIF('Order Tracking'!$M$5:$M$604,"Processing") -> 154 | G26: =IFERROR(F26/$A$5,0) -> 0.25666667
A27: 46082 | B27: =COUNTIFS('Order Tracking'!$B$5:$B$604,">="&A27,'Order Tracking'!$B$5:$B$604,"<"&EDATE(A27,1)) -> 63 | C27: =COUNTIFS('Order Tracking'!$B$5:$B$604,">="&A27,'Order Tracking'!$B$5:$B$604,"<"&EDATE(A27,1),'Order Tracking'!$M$5:$M$604,"Delivered") -> 44 | E27: Cancelled Orders | F27: =COUNTIF('Order Tracking'!$M$5:$M$604,"Cancelled") -> 41 | G27: =IFERROR(F27/$A$5,0) -> 0.068333333
A28: 46113 | B28: =COUNTIFS('Order Tracking'!$B$5:$B$604,">="&A28,'Order Tracking'!$B$5:$B$604,"<"&EDATE(A28,1)) -> 43 | C28: =COUNTIFS('Order Tracking'!$B$5:$B$604,">="&A28,'Order Tracking'!$B$5:$B$604,"<"&EDATE(A28,1),'Order Tracking'!$M$5:$M$604,"Delivered") -> 24
A29: 46143 | B29: =COUNTIFS('Order Tracking'!$B$5:$B$604,">="&A29,'Order Tracking'!$B$5:$B$604,"<"&EDATE(A29,1)) -> 53 | C29: =COUNTIFS('Order Tracking'!$B$5:$B$604,">="&A29,'Order Tracking'!$B$5:$B$604,"<"&EDATE(A29,1),'Order Tracking'!$M$5:$M$604,"Delivered") -> 30
A30: 46174 | B30: =COUNTIFS('Order Tracking'!$B$5:$B$604,">="&A30,'Order Tracking'!$B$5:$B$604,"<"&EDATE(A30,1)) -> 39 | C30: =COUNTIFS('Order Tracking'!$B$5:$B$604,">="&A30,'Order Tracking'!$B$5:$B$604,"<"&EDATE(A30,1),'Order Tracking'!$M$5:$M$604,"Delivered") -> 20
A31: 46204 | B31: =COUNTIFS('Order Tracking'!$B$5:$B$604,">="&A31,'Order Tracking'!$B$5:$B$604,"<"&EDATE(A31,1)) -> 48 | C31: =COUNTIFS('Order Tracking'!$B$5:$B$604,">="&A31,'Order Tracking'!$B$5:$B$604,"<"&EDATE(A31,1),'Order Tracking'!$M$5:$M$604,"Delivered") -> 28
A32: 46235 | B32: =COUNTIFS('Order Tracking'!$B$5:$B$604,">="&A32,'Order Tracking'!$B$5:$B$604,"<"&EDATE(A32,1)) -> 56 | C32: =COUNTIFS('Order Tracking'!$B$5:$B$604,">="&A32,'Order Tracking'!$B$5:$B$604,"<"&EDATE(A32,1),'Order Tracking'!$M$5:$M$604,"Delivered") -> 35
A33: 46266 | B33: =COUNTIFS('Order Tracking'!$B$5:$B$604,">="&A33,'Order Tracking'!$B$5:$B$604,"<"&EDATE(A33,1)) -> 54 | C33: =COUNTIFS('Order Tracking'!$B$5:$B$604,">="&A33,'Order Tracking'!$B$5:$B$604,"<"&EDATE(A33,1),'Order Tracking'!$M$5:$M$604,"Delivered") -> 26
A34: 46296 | B34: =COUNTIFS('Order Tracking'!$B$5:$B$604,">="&A34,'Order Tracking'!$B$5:$B$604,"<"&EDATE(A34,1)) -> 17 | C34: =COUNTIFS('Order Tracking'!$B$5:$B$604,">="&A34,'Order Tracking'!$B$5:$B$604,"<"&EDATE(A34,1),'Order Tracking'!$M$5:$M$604,"Delivered") -> 8
A37: Orders Requiring Immediate Management Attention (Top 20 Overdue Open Orders)
A38: Order ID | B38: Order Date | C38: Customer Name | D38: Region | E38: Product Name | F38: Order Value (₹) | G38: Order Status | H38: Expected Delivery | I38: Delay Reason
A39: ='Order Tracking'!A6 -> ORD0002 | B39: ='Order Tracking'!B6 -> 46161 | C39: ='Order Tracking'!D6 -> Diya Mishra | D39: ='Order Tracking'!E6 -> North | E39: ='Order Tracking'!H6 -> Eco Automotive Item 048 | F39: ='Order Tracking'!L6 -> 10672.08 | G39: ='Order Tracking'!M6 -> Dispatched | H39: ='Order Tracking'!O6 -> 46167 | I39: ='Order Tracking'!T6 -> Carrier delay
A40: ='Order Tracking'!A12 -> ORD0008 | B40: ='Order Tracking'!B12 -> 46017 | C40: ='Order Tracking'!D12 -> Ishaan Mishra | D40: ='Order Tracking'!E12 -> Central | E40: ='Order Tracking'!H12 -> Smart Home Item 018 | F40: ='Order Tracking'!L12 -> 34161.66 | G40: ='Order Tracking'!M12 -> Dispatched | H40: ='Order Tracking'!O12 -> 46019 | I40: ='Order Tracking'!T12 -> Carrier delay
A41: ='Order Tracking'!A15 -> ORD0011 | B41: ='Order Tracking'!B15 -> 45939 | C41: ='Order Tracking'!D15 -> Arjun Mishra | D41: ='Order Tracking'!E15 -> West | E41: ='Order Tracking'!H15 -> Compact Electronics Item 065 | F41: ='Order Tracking'!L15 -> 28691.08 | G41: ='Order Tracking'!M15 -> Dispatched | H41: ='Order Tracking'!O15 -> 45943 | I41: ='Order Tracking'!T15 -> Carrier delay
A42: ='Order Tracking'!A18 -> ORD0014 | B42: ='Order Tracking'!B18 -> 45979 | C42: ='Order Tracking'!D18 -> Ishaan Khan | D42: ='Order Tracking'!E18 -> North | E42: ='Order Tracking'!H18 -> Compact Personal Item 068 | F42: ='Order Tracking'!L18 -> 52123.4 | G42: ='Order Tracking'!M18 -> Dispatched | H42: ='Order Tracking'!O18 -> 45988 | I42: ='Order Tracking'!T18 -> Carrier delay
A43: ='Order Tracking'!A20 -> ORD0016 | B43: ='Order Tracking'!B20 -> 46130 | C43: ='Order Tracking'!D20 -> Ira Sharma | D43: ='Order Tracking'!E20 -> Central | E43: ='Order Tracking'!H20 -> Compact Apparel Item 087 | F43: ='Order Tracking'!L20 -> 109200.26 | G43: ='Order Tracking'!M20 -> Processing | H43: ='Order Tracking'!O20 -> 46134 | I43: ='Order Tracking'!T20 -> Warehouse backlog
A44: ='Order Tracking'!A28 -> ORD0024 | B44: ='Order Tracking'!B28 -> 46125 | C44: ='Order Tracking'!D28 -> Vivaan Das | D44: ='Order Tracking'!E28 -> West | E44: ='Order Tracking'!H28 -> Eco Office Item 043 | F44: ='Order Tracking'!L28 -> 35356.72 | G44: ='Order Tracking'!M28 -> Processing | H44: ='Order Tracking'!O28 -> 46129 | I44: ='Order Tracking'!T28 -> Awaiting stock
A45: ='Order Tracking'!A30 -> ORD0026 | B45: ='Order Tracking'!B30 -> 46219 | C45: ='Order Tracking'!D30 -> Vivaan Das | D45: ='Order Tracking'!E30 -> Central | E45: ='Order Tracking'!H30 -> Classic Home Item 026 | F45: ='Order Tracking'!L30 -> 29388.42 | G45: ='Order Tracking'!M30 -> Pending | H45: ='Order Tracking'!O30 -> 46221 | I45: ='Order Tracking'!T30 -> Warehouse backlog
A46: ='Order Tracking'!A32 -> ORD0028 | B46: ='Order Tracking'!B32 -> 46124 | C46: ='Order Tracking'!D32 -> Ira Iyer | D46: ='Order Tracking'!E32 -> West | E46: ='Order Tracking'!H32 -> Essential Home Item 010 | F46: ='Order Tracking'!L32 -> 118220 | G46: ='Order Tracking'!M32 -> Pending | H46: ='Order Tracking'!O32 -> 46132 | I46: ='Order Tracking'!T32 -> Warehouse backlog
A47: ='Order Tracking'!A36 -> ORD0032 | B47: ='Order Tracking'!B36 -> 46178 | C47: ='Order Tracking'!D36 -> Aditi Sharma | D47: ='Order Tracking'!E36 -> West | E47: ='Order Tracking'!H36 -> Essential Industrial Item 045 | F47: ='Order Tracking'!L36 -> 148633.95 | G47: ='Order Tracking'!M36 -> Processing | H47: ='Order Tracking'!O36 -> 46187 | I47: ='Order Tracking'!T36 -> Awaiting stock
...

Sheet Supplier Performance Dashboard
A1: SUPPLIER PERFORMANCE & RELIABILITY DASHBOARD
A2: Evaluates 25 suppliers on purchase volume, delivery lead time, on-time delivery %, quality rate, composite score, and performance tier.
A4: Total Suppliers | C4: Active Suppliers | E4: Total Purchase Value | G4: Avg Supplier Delivery Time
A5: =COUNTA('Supplier Database'!$A$5:$A$29) -> 25 | C5: =COUNTIF('Supplier Database'!$K$5:$K$29,"Active") -> 24 | E5: =SUM('Purchase Management'!$I$5:$I$224) -> 2.3810373e+08 | G5: =IFERROR(AVERAGE(G12:G36),0) -> 9.3339632
A7: On-Time Delivery % | C7: Defective Items % | E7: Average Supplier Rating
A8: =IFERROR(SUM(E12:E36)/(SUM(E12:E36)+SUM(F12:F36)),0) -> 0.50793651 | C8: =IFERROR(SUM(H12:H36)/SUM('Purchase Management'!$G$5:$G$224),0) -> 0.018246767 | E8: =AVERAGE('Supplier Database'!$J$5:$J$29) -> 4.016
A10: Supplier Performance Scorecard (All 25 Suppliers)
A11: Supplier ID | B11: Supplier Name | C11: Total Purchase Orders | D11: Total Purchase Value | E11: On-Time Deliveries | F11: Late Deliveries | G11: Average Delivery Time | H11: Defective Units | I11: Quality Rate | J11: On-Time % | K11: Supplier Performance Score | L11: Performance Category
A12: SUP001 | B12: =VLOOKUP(A12,'Supplier Database'!$A$5:$K$29,2,FALSE()) -> Apex Supplies | C12: =COUNTIF('Purchase Management'!$C$5:$C$224,A12) -> 4 | D12: =SUMIF('Purchase Management'!$C$5:$C$224,A12,'Purchase Management'!$I$5:$I$224) -> 2246214.5 | E12: =COUNTIFS('Purchase Management'!$C$5:$C$224,A12,'Purchase Management'!$N$5:$N$224,"Received",'Purchase Management'!$O$5:$O$224,0) -> 3 | F12: =COUNTIFS('Purchase Management'!$C$5:$C$224,A12,'Purchase Management'!$O$5:$O$224,">0") -> 1 | G12: =VLOOKUP(A12,'Supplier Database'!$A$5:$K$29,9,FALSE())+IFERROR(AVERAGEIF('Purchase Management'!$C$5:$C$224,A12,'Purchase Management'!$O$5:$O$224),0) -> 4.5 | H12: =ROUND(SUMIF('Purchase Management'!$C$5:$C$224,A12,'Purchase Management'!$G$5:$G$224)*(5.5-VLOOKUP(A12,'Supplier Database'!$A$5:$K$29,10,FALSE()))*0.012,0) -> 15 | I12: =IFERROR(1-H12/MAX(1,SUMIF('Purchase Management'!$C$5:$C$224,A12,'Purchase Management'!$G$5:$G$224)),1) -> 0.98705781 | J12: =IFERROR(E12/MAX(1,E12+F12),0) -> 0.75 | K12: =ROUND(0.45*J12*100+0.35*I12*100+0.2*(VLOOKUP(A12,'Supplier Database'!$A$5:$K$29,10,FALSE())*20),1) -> 85.9 | L12: =IF(K12>=85,"Excellent",IF(K12>=75,"Good",IF(K12>=65,"Average","Poor"))) -> Excellent
A13: SUP002 | B13: =VLOOKUP(A13,'Supplier Database'!$A$5:$K$29,2,FALSE()) -> Bright Distributors | C13: =COUNTIF('Purchase Management'!$C$5:$C$224,A13) -> 9 | D13: =SUMIF('Purchase Management'!$C$5:$C$224,A13,'Purchase Management'!$I$5:$I$224) -> 7825955.3 | E13: =COUNTIFS('Purchase Management'!$C$5:$C$224,A13,'Purchase Management'!$N$5:$N$224,"Received",'Purchase Management'!$O$5:$O$224,0) -> 4 | F13: =COUNTIFS('Purchase Management'!$C$5:$C$224,A13,'Purchase Management'!$O$5:$O$224,">0") -> 4 | G13: =VLOOKUP(A13,'Supplier Database'!$A$5:$K$29,9,FALSE())+IFERROR(AVERAGEIF('Purchase Management'!$C$5:$C$224,A13,'Purchase Management'!$O$5:$O$224),0) -> 9.5555556 | H13: =ROUND(SUMIF('Purchase Management'!$C$5:$C$224,A13,'Purchase Management'!$G$5:$G$224)*(5.5-VLOOKUP(A13,'Supplier Database'!$A$5:$K$29,10,FALSE()))*0.012,0) -> 69 | I13: =IFERROR(1-H13/MAX(1,SUMIF('Purchase Management'!$C$5:$C$224,A13,'Purchase Management'!$G$5:$G$224)),1) -> 0.97370427 | J13: =IFERROR(E13/MAX(1,E13+F13),0) -> 0.5 | K13: =ROUND(0.45*J13*100+0.35*I13*100+0.2*(VLOOKUP(A13,'Supplier Database'!$A$5:$K$29,10,FALSE())*20),1) -> 69.8 | L13: =IF(K13>=85,"Excellent",IF(K13>=75,"Good",IF(K13>=65,"Average","Poor"))) -> Average
A14: SUP003 | B14: =VLOOKUP(A14,'Supplier Database'!$A$5:$K$29,2,FALSE()) -> Core Industries | C14: =COUNTIF('Purchase Management'!$C$5:$C$224,A14) -> 3 | D14: =SUMIF('Purchase Management'!$C$5:$C$224,A14,'Purchase Management'!$I$5:$I$224) -> 2086946.9 | E14: =COUNTIFS('Purchase Management'!$C$5:$C$224,A14,'Purchase Management'!$N$5:$N$224,"Received",'Purchase Management'!$O$5:$O$224,0) -> 0 | F14: =COUNTIFS('Purchase Management'!$C$5:$C$224,A14,'Purchase Management'!$O$5:$O$224,">0") -> 3 | G14: =VLOOKUP(A14,'Supplier Database'!$A$5:$K$29,9,FALSE())+IFERROR(AVERAGEIF('Purchase Management'!$C$5:$C$224,A14,'Purchase Management'!$O$5:$O$224),0) -> 7.6666667 | H14: =ROUND(SUMIF('Purchase Management'!$C$5:$C$224,A14,'Purchase Management'!$G$5:$G$224)*(5.5-VLOOKUP(A14,'Supplier Database'!$A$5:$K$29,10,FALSE()))*0.012,0) -> 25 | I14: =IFERROR(1-H14/MAX(1,SUMIF('Purchase Management'!$C$5:$C$224,A14,'Purchase Management'!$G$5:$G$224)),1) -> 0.9682338 | J14: =IFERROR(E14/MAX(1,E14+F14),0) -> 0 | K14: =ROUND(0.45*J14*100+0.35*I14*100+0.2*(VLOOKUP(A14,'Supplier Database'!$A$5:$K$29,10,FALSE())*20),1) -> 45.5 | L14: =IF(K14>=85,"Excellent",IF(K14>=75,"Good",IF(K14>=65,"Average","Poor"))) -> Poor
A15: SUP004 | B15: =VLOOKUP(A15,'Supplier Database'!$A$5:$K$29,2,FALSE()) -> Delta Trading Co. | C15: =COUNTIF('Purchase Management'!$C$5:$C$224,A15) -> 10 | D15: =SUMIF('Purchase Management'!$C$5:$C$224,A15,'Purchase Management'!$I$5:$I$224) -> 20947982 | E15: =COUNTIFS('Purchase Management'!$C$5:$C$224,A15,'Purchase Management'!$N$5:$N$224,"Received",'Purchase Management'!$O$5:$O$224,0) -> 4 | F15: =COUNTIFS('Purchase Management'!$C$5:$C$224,A15,'Purchase Management'!$O$5:$O$224,">0") -> 4 | G15: =VLOOKUP(A15,'Supplier Database'!$A$5:$K$29,9,FALSE())+IFERROR(AVERAGEIF('Purchase Management'!$C$5:$C$224,A15,'Purchase Management'!$O$5:$O$224),0) -> 11.4 | H15: =ROUND(SUMIF('Purchase Management'!$C$5:$C$224,A15,'Purchase Management'!$G$5:$G$224)*(5.5-VLOOKUP(A15,'Supplier Database'!$A$5:$K$29,10,FALSE()))*0.012,0) -> 86 | I15: =IFERROR(1-H15/MAX(1,SUMIF('Purchase Management'!$C$5:$C$224,A15,'Purchase Management'!$G$5:$G$224)),1) -> 0.97490516 | J15: =IFERROR(E15/MAX(1,E15+F15),0) -> 0.5 | K15: =ROUND(0.45*J15*100+0.35*I15*100+0.2*(VLOOKUP(A15,'Supplier Database'!$A$5:$K$29,10,FALSE())*20),1) -> 70.2 | L15: =IF(K15>=85,"Excellent",IF(K15>=75,"Good",IF(K15>=65,"Average","Poor"))) -> Average
A16: SUP005 | B16: =VLOOKUP(A16,'Supplier Database'!$A$5:$K$29,2,FALSE()) -> Ever Logistics | C16: =COUNTIF('Purchase Management'!$C$5:$C$224,A16) -> 11 | D16: =SUMIF('Purchase Management'!$C$5:$C$224,A16,'Purchase Management'!$I$5:$I$224) -> 11196676 | E16: =COUNTIFS('Purchase Management'!$C$5:$C$224,A16,'Purchase Management'!$N$5:$N$224,"Received",'Purchase Management'!$O$5:$O$224,0) -> 7 | F16: =COUNTIFS('Purchase Management'!$C$5:$C$224,A16,'Purchase Management'!$O$5:$O$224,">0") -> 2 | G16: =VLOOKUP(A16,'Supplier Database'!$A$5:$K$29,9,FALSE())+IFERROR(AVERAGEIF('Purchase Management'!$C$5:$C$224,A16,'Purchase Management'!$O$5:$O$224),0) -> 3.2727273 | H16: =ROUND(SUMIF('Purchase Management'!$C$5:$C$224,A16,'Purchase Management'!$G$5:$G$224)*(5.5-VLOOKUP(A16,'Supplier Database'!$A$5:$K$29,10,FALSE()))*0.012,0) -> 39 | I16: =IFERROR(1-H16/MAX(1,SUMIF('Purchase Management'!$C$5:$C$224,A16,'Purchase Management'!$G$5:$G$224)),1) -> 0.98792196 | J16: =IFERROR(E16/MAX(1,E16+F16),0) -> 0.77777778 | K16: =ROUND(0.45*J16*100+0.35*I16*100+0.2*(VLOOKUP(A16,'Supplier Database'!$A$5:$K$29,10,FALSE())*20),1) -> 87.6 | L16: =IF(K16>=85,"Excellent",IF(K16>=75,"Good",IF(K16>=65,"Average","Poor"))) -> Excellent
A17: SUP006 | B17: =VLOOKUP(A17,'Supplier Database'!$A$5:$K$29,2,FALSE()) -> Frontier Wholesale | C17: =COUNTIF('Purchase Management'!$C$5:$C$224,A17) -> 9 | D17: =SUMIF('Purchase Management'!$C$5:$C$224,A17,'Purchase Management'!$I$5:$I$224) -> 9951347.4 | E17: =COUNTIFS('Purchase Management'!$C$5:$C$224,A17,'Purchase Management'!$N$5:$N$224,"Received",'Purchase Management'!$O$5:$O$224,0) -> 2 | F17: =COUNTIFS('Purchase Management'!$C$5:$C$224,A17,'Purchase Management'!$O$5:$O$224,">0") -> 5 | G17: =VLOOKUP(A17,'Supplier Database'!$A$5:$K$29,9,FALSE())+IFERROR(AVERAGEIF('Purchase Management'!$C$5:$C$224,A17,'Purchase Management'!$O$5:$O$224),0) -> 13.444444 | H17: =ROUND(SUMIF('Purchase Management'!$C$5:$C$224,A17,'Purchase Management'!$G$5:$G$224)*(5.5-VLOOKUP(A17,'Supplier Database'!$A$5:$K$29,10,FALSE()))*0.012,0) -> 43 | I17: =IFERROR(1-H17/MAX(1,SUMIF('Purchase Management'!$C$5:$C$224,A17,'Purchase Management'!$G$5:$G$224)),1) -> 0.98426637 | J17: =IFERROR(E17/MAX(1,E17+F17),0) -> 0.28571429 | K17: =ROUND(0.45*J17*100+0.35*I17*100+0.2*(VLOOKUP(A17,'Supplier Database'!$A$5:$K$29,10,FALSE())*20),1) -> 64.1 | L17: =IF(K17>=85,"Excellent",IF(K17>=75,"Good",IF(K17>=65,"Average","Poor"))) -> Poor
A18: SUP007 | B18: =VLOOKUP(A18,'Supplier Database'!$A$5:$K$29,2,FALSE()) -> Global Partners | C18: =COUNTIF('Purchase Management'!$C$5:$C$224,A18) -> 7 | D18: =SUMIF('Purchase Management'!$C$5:$C$224,A18,'Purchase Management'!$I$5:$I$224) -> 8152619.9 | E18: =COUNTIFS('Purchase Management'!$C$5:$C$224,A18,'Purchase Management'!$N$5:$N$224,"Received",'Purchase Management'!$O$5:$O$224,0) -> 4 | F18: =COUNTIFS('Purchase Management'!$C$5:$C$224,A18,'Purchase Management'!$O$5:$O$224,">0") -> 3 | G18: =VLOOKUP(A18,'Supplier Database'!$A$5:$K$29,9,FALSE())+IFERROR(AVERAGEIF('Purchase Management'!$C$5:$C$224,A18,'Purchase Management'!$O$5:$O$224),0) -> 15.571429 | H18: =ROUND(SUMIF('Purchase Management'!$C$5:$C$224,A18,'Purchase Management'!$G$5:$G$224)*(5.5-VLOOKUP(A18,'Supplier Database'!$A$5:$K$29,10,FALSE()))*0.012,0) -> 25 | I18: =IFERROR(1-H18/MAX(1,SUMIF('Purchase Management'!$C$5:$C$224,A18,'Purchase Management'!$G$5:$G$224)),1) -> 0.98903509 | J18: =IFERROR(E18/MAX(1,E18+F18),0) -> 0.57142857 | K18: =ROUND(0.45*J18*100+0.35*I18*100+0.2*(VLOOKUP(A18,'Supplier Database'!$A$5:$K$29,10,FALSE())*20),1) -> 78.7 | L18: =IF(K18>=85,"Excellent",IF(K18>=75,"Good",IF(K18>=65,"Average","Poor"))) -> Good
A19: SUP008 | B19: =VLOOKUP(A19,'Supplier Database'!$A$5:$K$29,2,FALSE()) -> Horizon Supplies | C19: =COUNTIF('Purchase Management'!$C$5:$C$224,A19) -> 11 | D19: =SUMIF('Purchase Management'!$C$5:$C$224,A19,'Purchase Management'!$I$5:$I$224) -> 8308347.5 | E19: =COUNTIFS('Purchase Management'!$C$5:$C$224,A19,'Purchase Management'!$N$5:$N$224,"Received",'Purchase Management'!$O$5:$O$224,0) -> 7 | F19: =COUNTIFS('Purchase Management'!$C$5:$C$224,A19,'Purchase Management'!$O$5:$O$224,">0") -> 2 | G19: =VLOOKUP(A19,'Supplier Database'!$A$5:$K$29,9,FALSE())+IFERROR(AVERAGEIF('Purchase Management'!$C$5:$C$224,A19,'Purchase Management'!$O$5:$O$224),0) -> 5.6363636 | H19: =ROUND(SUMIF('Purchase Management'!$C$5:$C$224,A19,'Purchase Management'!$G$5:$G$224)*(5.5-VLOOKUP(A19,'Supplier Database'!$A$5:$K$29,10,FALSE()))*0.012,0) -> 37 | I19: =IFERROR(1-H19/MAX(1,SUMIF('Purchase Management'!$C$5:$C$224,A19,'Purchase Management'!$G$5:$G$224)),1) -> 0.98453177 | J19: =IFERROR(E19/MAX(1,E19+F19),0) -> 0.77777778 | K19: =ROUND(0.45*J19*100+0.35*I19*100+0.2*(VLOOKUP(A19,'Supplier Database'!$A$5:$K$29,10,FALSE())*20),1) -> 86.3 | L19: =IF(K19>=85,"Excellent",IF(K19>=75,"Good",IF(K19>=65,"Average","Poor"))) -> Excellent
A20: SUP009 | B20: =VLOOKUP(A20,'Supplier Database'!$A$5:$K$29,2,FALSE()) -> Indus Distributors | C20: =COUNTIF('Purchase Management'!$C$5:$C$224,A20) -> 4 | D20: =SUMIF('Purchase Management'!$C$5:$C$224,A20,'Purchase Management'!$I$5:$I$224) -> 4328441.5 | E20: =COUNTIFS('Purchase Management'!$C$5:$C$224,A20,'Purchase Management'!$N$5:$N$224,"Received",'Purchase Management'!$O$5:$O$224,0) -> 3 | F20: =COUNTIFS('Purchase Management'!$C$5:$C$224,A20,'Purchase Management'!$O$5:$O$224,">0") -> 1 | G20: =VLOOKUP(A20,'Supplier Database'!$A$5:$K$29,9,FALSE())+IFERROR(AVERAGEIF('Purchase Management'!$C$5:$C$224,A20,'Purchase Management'!$O$5:$O$224),0) -> 9.5 | H20: =ROUND(SUMIF('Purchase Management'!$C$5:$C$224,A20,'Purchase Management'!$G$5:$G$224)*(5.5-VLOOKUP(A20,'Supplier Database'!$A$5:$K$29,10,FALSE()))*0.012,0) -> 7 | I20: =IFERROR(1-H20/MAX(1,SUMIF('Purchase Management'!$C$5:$C$224,A20,'Purchase Management'!$G$5:$G$224)),1) -> 0.99314398 | J20: =IFERROR(E20/MAX(1,E20+F20),0) -> 0.75 | K20: =ROUND(0.45*J20*100+0.35*I20*100+0.2*(VLOOKUP(A20,'Supplier Database'!$A$5:$K$29,10,FALSE())*20),1) -> 88.1 | L20: =IF(K20>=85,"Excellent",IF(K20>=75,"Good",IF(K20>=65,"Average","Poor"))) -> Excellent
A21: SUP010 | B21: =VLOOKUP(A21,'Supplier Database'!$A$5:$K$29,2,FALSE()) -> Jupiter Industries | C21: =COUNTIF('Purchase Management'!$C$5:$C$224,A21) -> 12 | D21: =SUMIF('Purchase Management'!$C$5:$C$224,A21,'Purchase Management'!$I$5:$I$224) -> 12994660 | E21: =COUNTIFS('Purchase Management'!$C$5:$C$224,A21,'Purchase Management'!$N$5:$N$224,"Received",'Purchase Management'!$O$5:$O$224,0) -> 7 | F21: =COUNTIFS('Purchase Management'!$C$5:$C$224,A21,'Purchase Management'!$O$5:$O$224,">0") -> 2 | G21: =VLOOKUP(A21,'Supplier Database'!$A$5:$K$29,9,FALSE())+IFERROR(AVERAGEIF('Purchase Management'!$C$5:$C$224,A21,'Purchase Management'!$O$5:$O$224),0) -> 14.666667 | H21: =ROUND(SUMIF('Purchase Management'!$C$5:$C$224,A21,'Purchase Management'!$G$5:$G$224)*(5.5-VLOOKUP(A21,'Supplier Database'!$A$5:$K$29,10,FALSE()))*0.012,0) -> 40 | I21: =IFERROR(1-H21/MAX(1,SUMIF('Purchase Management'!$C$5:$C$224,A21,'Purchase Management'!$G$5:$G$224)),1) -> 0.98786776 | J21: =IFERROR(E21/MAX(1,E21+F21),0) -> 0.77777778 | K21: =ROUND(0.45*J21*100+0.35*I21*100+0.2*(VLOOKUP(A21,'Supplier Database'!$A$5:$K$29,10,FALSE())*20),1) -> 87.6 | L21: =IF(K21>=85,"Excellent",IF(K21>=75,"Good",IF(K21>=65,"Average","Poor"))) -> Excellent
A22: SUP011 | B22: =VLOOKUP(A22,'Supplier Database'!$A$5:$K$29,2,FALSE()) -> Kinetic Trading Co. | C22: =COUNTIF('Purchase Management'!$C$5:$C$224,A22) -> 11 | D22: =SUMIF('Purchase Management'!$C$5:$C$224,A22,'Purchase Management'!$I$5:$I$224) -> 9110465.2 | E22: =COUNTIFS('Purchase Management'!$C$5:$C$224,A22,'Purchase Management'!$N$5:$N$224,"Received",'Purchase Management'!$O$5:$O$224,0) -> 4 | F22: =COUNTIFS('Purchase Management'!$C$5:$C$224,A22,'Purchase Management'!$O$5:$O$224,">0") -> 5 | G22: =VLOOKUP(A22,'Supplier Database'!$A$5:$K$29,9,FALSE())+IFERROR(AVERAGEIF('Purchase Management'!$C$5:$C$224,A22,'Purchase Management'!$O$5:$O$224),0) -> 13.272727 | H22: =ROUND(SUMIF('Purchase Management'!$C$5:$C$224,A22,'Purchase Management'!$G$5:$G$224)*(5.5-VLOOKUP(A22,'Supplier Database'!$A$5:$K$29,10,FALSE()))*0.012,0) -> 18 | I22: =IFERROR(1-H22/MAX(1,SUMIF('Purchase Management'!$C$5:$C$224,A22,'Purchase Management'!$G$5:$G$224)),1) -> 0.99048626 | J22: =IFERROR(E22/MAX(1,E22+F22),0) -> 0.44444444 | K22: =ROUND(0.45*J22*100+0.35*I22*100+0.2*(VLOOKUP(A22,'Supplier Database'!$A$5:$K$29,10,FALSE())*20),1) -> 73.5 | L22: =IF(K22>=85,"Excellent",IF(K22>=75,"Good",IF(K22>=65,"Average","Poor"))) -> Average
A23: SUP012 | B23: =VLOOKUP(A23,'Supplier Database'!$A$5:$K$29,2,FALSE()) -> Lotus Logistics | C23: =COUNTIF('Purchase Management'!$C$5:$C$224,A23) -> 10 | D23: =SUMIF('Purchase Management'!$C$5:$C$224,A23,'Purchase Management'!$I$5:$I$224) -> 13330848 | E23: =COUNTIFS('Purchase Management'!$C$5:$C$224,A23,'Purchase Management'!$N$5:$N$224,"Received",'Purchase Management'!$O$5:$O$224,0) -> 7 | F23: =COUNTIFS('Purchase Management'!$C$5:$C$224,A23,'Purchase Management'!$O$5:$O$224,">0") -> 3 | G23: =VLOOKUP(A23,'Supplier Database'!$A$5:$K$29,9,FALSE())+IFERROR(AVERAGEIF('Purchase Management'!$C$5:$C$224,A23,'Purchase Management'!$O$5:$O$224),0) -> 11.3 | H23: =ROUND(SUMIF('Purchase Management'!$C$5:$C$224,A23,'Purchase Management'!$G$5:$G$224)*(5.5-VLOOKUP(A23,'Supplier Database'!$A$5:$K$29,10,FALSE()))*0.012,0) -> 26 | I23: =IFERROR(1-H23/MAX(1,SUMIF('Purchase Management'!$C$5:$C$224,A23,'Purchase Management'!$G$5:$G$224)),1) -> 0.98925176 | J23: =IFERROR(E23/MAX(1,E23+F23),0) -> 0.7 | K23: =ROUND(0.45*J23*100+0.35*I23*100+0.2*(VLOOKUP(A23,'Supplier Database'!$A$5:$K$29,10,FALSE())*20),1) -> 84.5 | L23: =IF(K23>=85,"Excellent",IF(K23>=75,"Good",IF(K23>=65,"Average","Poor"))) -> Good
... A36: SUP025 | B36: =VLOOKUP(A36,'Supplier Database'!$A$5:$K$29,2,FALSE()) -> Zenith Trading Co. | C36: =COUNTIF('Purchase Management'!$C$5:$C$224,A36) -> 12 | D36: =SUMIF('Purchase Management'!$C$5:$C$224,A36,'Purchase Management'!$I$5:$I$224) -> 14661700 | E36: =COUNTIFS('Purchase Management'!$C$5:$C$224,A36,'Purchase Management'!$N$5:$N$224,"Received",'Purchase Management'!$O$5:$O$224,0) -> 6 | F36: =COUNTIFS('Purchase Management'!$C$5:$C$224,A36,'Purchase Management'!$O$5:$O$224,">0") -> 5 | G36: =VLOOKUP(A36,'Supplier Database'!$A$5:$K$29,9,FALSE())+IFERROR(AVERAGEIF('Purchase Management'!$C$5:$C$224,A36,'Purchase Management'!$O$5:$O$224),0) -> 6 | H36: =ROUND(SUMIF('Purchase Management'!$C$5:$C$224,A36,'Purchase Management'!$G$5:$G$224)*(5.5-VLOOKUP(A36,'Supplier Database'!$A$5:$K$29,10,FALSE()))*0.012,0) -> 53 | I36: =IFERROR(1-H36/MAX(1,SUMIF('Purchase Management'!$C$5:$C$224,A36,'Purchase Management'!$G$5:$G$224)),1) -> 0.98554677 | J36: =IFERROR(E36/MAX(1,E36+F36),0) -> 0.54545455 | K36: =ROUND(0.45*J36*100+0.35*I36*100+0.2*(VLOOKUP(A36,'Supplier Database'!$A$5:$K$29,10,FALSE())*20),1) -> 76.2 | L36: =IF(K36>=85,"Excellent",IF(K36>=75,"Good",IF(K36>=65,"Average","Poor"))) -> Good

Sheet Product Performance Dashboard
A1: PRODUCT PERFORMANCE & PROFITABILITY DASHBOARD
A2: SKU-level demand, sales revenue, unit profitability, category contribution, return rates, and inventory risk signals.
A4: Total Products | C4: Total Units Sold | E4: Total Sales Revenue | G4: Average Selling Price
A5: =COUNTA('Product Master'!$A$5:$A$104) -> 100 | C5: =SUM(C24:C123) -> 8034 | E5: =SUM(D24:D123) -> 49134145 | G5: =AVERAGE('Product Master'!$F$5:$F$104) -> 5883.8146
A7: Best-Selling Product | C7: Lowest-Selling Product | E7: Product Return Rate | G7: Total Gross Profit
A8: =INDEX(A24:A123,MATCH(MAX(C24:C123),C24:C123,0)) -> PRD062 | C8: =INDEX(A24:A123,MATCH(MIN(C24:C123),C24:C123,0)) -> PRD024 | E8: =IFERROR(SUM('Inventory Management'!$J$5:$J$104)/SUM('Inventory Management'!$I$5:$I$104),0) -> 0.0085756398 | G8: =SUM(I24:I123) -> 14577584
A11: Revenue & Profitability by Product Category
A12: Product Category | B12: Units Sold | C12: Sales Revenue (₹) | D12: Gross Profit (₹) | E12: Return Rate
A13: Electronics | B13: =SUMIF(E24:E123,A13,C24:C123) -> 1026 | C13: =SUMIF(E24:E123,A13,D24:D123) -> 7418459.1 | D13: =SUMIF(E24:E123,A13,I24:I123) -> 2333398.4 | E13: =IFERROR(SUMIF('Inventory Management'!$C$5:$C$104,A13,'Inventory Management'!$J$5:$J$104)/SUMIF('Inventory Management'!$C$5:$C$104,A13,'Inventory Management'!$I$5:$I$104),0) -> 0.016059957
A14: Home & Kitchen | B14: =SUMIF(E24:E123,A14,C24:C123) -> 995 | C14: =SUMIF(E24:E123,A14,D24:D123) -> 6359299.4 | D14: =SUMIF(E24:E123,A14,I24:I123) -> 1600191.7 | E14: =IFERROR(SUMIF('Inventory Management'!$C$5:$C$104,A14,'Inventory Management'!$J$5:$J$104)/SUMIF('Inventory Management'!$C$5:$C$104,A14,'Inventory Management'!$I$5:$I$104),0) -> 0.0031545741
A15: Office Supplies | B15: =SUMIF(E24:E123,A15,C24:C123) -> 1140 | C15: =SUMIF(E24:E123,A15,D24:D123) -> 5066638.8 | D15: =SUMIF(E24:E123,A15,I24:I123) -> 1541791.7 | E15: =IFERROR(SUMIF('Inventory Management'!$C$5:$C$104,A15,'Inventory Management'!$J$5:$J$104)/SUMIF('Inventory Management'!$C$5:$C$104,A15,'Inventory Management'!$I$5:$I$104),0) -> 0.0057088487
A16: Personal Care | B16: =SUMIF(E24:E123,A16,C24:C123) -> 886 | C16: =SUMIF(E24:E123,A16,D24:D123) -> 5583999.6 | D16: =SUMIF(E24:E123,A16,I24:I123) -> 1670028.7 | E16: =IFERROR(SUMIF('Inventory Management'!$C$5:$C$104,A16,'Inventory Management'!$J$5:$J$104)/SUMIF('Inventory Management'!$C$5:$C$104,A16,'Inventory Management'!$I$5:$I$104),0) -> 0.0034924331
A17: Industrial | B17: =SUMIF(E24:E123,A17,C24:C123) -> 1139 | C17: =SUMIF(E24:E123,A17,D24:D123) -> 7605893.4 | D17: =SUMIF(E24:E123,A17,I24:I123) -> 2207153.6 | E17: =IFERROR(SUMIF('Inventory Management'!$C$5:$C$104,A17,'Inventory Management'!$J$5:$J$104)/SUMIF('Inventory Management'!$C$5:$C$104,A17,'Inventory Management'!$I$5:$I$104),0) -> 0.011976048
A18: Packaging | B18: =SUMIF(E24:E123,A18,C24:C123) -> 992 | C18: =SUMIF(E24:E123,A18,D24:D123) -> 6074915.3 | D18: =SUMIF(E24:E123,A18,I24:I123) -> 1965801.5 | E18: =IFERROR(SUMIF('Inventory Management'!$C$5:$C$104,A18,'Inventory Management'!$J$5:$J$104)/SUMIF('Inventory Management'!$C$5:$C$104,A18,'Inventory Management'!$I$5:$I$104),0) -> 0.0030991736
A19: Apparel | B19: =SUMIF(E24:E123,A19,C24:C123) -> 919 | C19: =SUMIF(E24:E123,A19,D24:D123) -> 6042303.9 | D19: =SUMIF(E24:E123,A19,I24:I123) -> 1963784.5 | E19: =IFERROR(SUMIF('Inventory Management'!$C$5:$C$104,A19,'Inventory Management'!$J$5:$J$104)/SUMIF('Inventory Management'!$C$5:$C$104,A19,'Inventory Management'!$I$5:$I$104),0) -> 0.0024660912
